Workbook

Sheet SOV&REPLICA
A1: Policy ID | B1: Country Policy | C1: Region | D1: Country | E1: Policy Holder | F1: Policy Type | G1: Crop Type | H1: Peril | I1: Pool | J1: Policy Years | K1: Premium | L1: Attachment | M1: Exhaustion | N1: Ceding % | O1: Coverage | P1: Claims | Q1: Rate-On-Line | R1: Premium Loading | S1: Expected Loss | T1: Premium Financed by Country | U1: Premium Financed by KFW | V1: Premium Financed by ADRiFi ADF | W1: Premium Financed by ADRiFi MDTF | X1: Premium Financed by US AID | Y1: Premium Financed by START Network | Z1: Premium Financed by WFP | AA1: Premium Financed by SDC | AB1: Premium Financed by FCDO | AC1: Premium Financed by Global Shield | AD1: Premium Financed by UNHCR
A2: 12_DR_BJ_CROP_SOV_NORD | B2: =UPPER([1]Pools!$B399) | C2: WCA | D2: BENIN | E2: Country | F2: SOVEREIGN | G2: CROP | H2: Drought | I2: 12A | J2: 2025/2026 | K2: 339278 | L2: 12384366 | M2: 23349472 | N2: 0.16 | O2: 1754417 | Q2: 0.19338504 | R2: 1.6 | S2: =K2/R2 -> 212048.75 | W2: 339278
A3: 12_DR_BJ_CROP_SOV_SUD | B3: =UPPER([1]Pools!$B400) | C3: WCA | D3: BENIN | E3: Country | F3: SOVEREIGN | G3: CROP | H3: Drought | I3: 12A | J3: 2025/2026 | K3: 470022 | L3: 12970840 | M3: 42734054 | N3: 0.067197044 | O3: 2000000 | P3: 1467765 | Q3: 0.235011 | R3: 1.6 | S3: =K3/R3 -> 293763.75 | W3: 470022
A4: 12_DR_BF_CROP_SOV | B4: =UPPER([1]Pools!$B401) -> POOL XII | C4: WCA | D4: BURKINA FASO | E4: Country | F4: SOVEREIGN | G4: CROP | H4: Drought | I4: 12A | J4: 2025/2026 | K4: 1225493 | L4: 45978150 | M4: 90895230 | N4: 0.14439999 | O4: 6486026 | Q4: 0.18894358 | R4: 1.6 | S4: =K4/R4 -> 765933.12 | T4: 200000 | W4: 500000
A5: 12_DR_BF_CROP_RANGE | B5: =UPPER([1]Pools!$B402) -> BENIN NORD | C5: WCA | D5: BURKINA FASO | E5: Country | F5: SOVEREIGN | G5: RANGELAND | H5: Drought | I5: 12A | J5: 2025/2026 | K5: 174507 | L5: 21182555 | M5: 43373688 | N5: 0.033797283 | O5: 750000 | Q5: 0.232676 | R5: 1.6 | S5: =K5/R5 -> 109066.88 | T5: 200000 | W5: 500000
A6: 12_DR_CI_CROP_SOV_CENTRE | B6: =UPPER([1]Pools!$B403) -> BENIN SUD PETITE | C6: WCA | D6: CÔTE D'IVOIRE | E6: Country | F6: SOVEREIGN | G6: CROP | H6: Drought | I6: 12A | J6: 2025/2026 | K6: 750000 | L6: 4675200 | M6: 28495743 | N6: 0.16999999 | O6: 4049492 | Q6: 0.18520842 | R6: 1.6 | S6: =K6/R6 -> 468750 | T6: 750000
A7: 12_DR_CI_CROP_SOV_NORD | B7: =UPPER([1]Pools!$B404) -> BURKINA FASO CROP | C7: WCA | D7: CÔTE D'IVOIRE | E7: Country | F7: SOVEREIGN | G7: CROP | H7: Drought | I7: 12A | J7: 2025/2026 | K7: 750000 | L7: 7515075 | M7: 41918371 | N7: 0.125 | O7: 4300412 | P7: 435203 | Q7: 0.17440189 | R7: 1.6 | S7: =K7/R7 -> 468750 | T7: 750000
A8: 12_DR_GH_CROP_SOV_NORTH | B8: =UPPER([1]Pools!$B405) -> BURKINA FASO RANGELAND | C8: WCA | D8: GHANA | E8: Country | F8: SOVEREIGN | G8: CROP | H8: Drought | I8: 12A | J8: 2025/2026 | K8: 650000 | L8: 5384400 | M8: 40147240 | N8: 0.090884425 | O8: 3159400.7 | P8: 1100072.3 | Q8: 0.20573522 | R8: 1.6 | S8: =K8/R8 -> 406250 | U8: 400000 | AC8: 250000
A9: 12_DR_GH_CROP_SOV_SOUTH | B9: =UPPER([1]Pools!$B406) -> CÔTE D'IVOIRE CENTRE | C9: WCA | D9: GHANA | E9: Country | F9: SOVEREIGN | G9: CROP | H9: Drought | I9: 12A | J9: 2025/2026 | K9: 650000 | L9: 12386420 | M9: 21090000 | N9: 0.27779339 | O9: 2417797 | Q9: 0.26883977 | R9: 1.6 | S9: =K9/R9 -> 406250 | U9: 400000 | AC9: 250000
A10: 12_DR_ML_CROP_SOV | B10: =UPPER([1]Pools!$B407) -> CÔTE D'IVOIRE NORD | C10: WCA | D10: MALI | E10: Country | F10: SOVEREIGN | G10: CROP | H10: Drought | I10: 12A | J10: 2025/2026 | K10: 1500000 | L10: 31126675 | M10: 61513361 | N10: 0.26611155 | O10: 8086248 | Q10: 0.18550012 | R10: 1.6 | S10: =K10/R10 -> 937500 | U10: 500000 | V10: 1000000
A11: 12_DR_MR_CROP_SOV_NORD | B11: =UPPER([1]Pools!$B408) -> GHANA NORTH | C11: WCA | D11: MAURITANIA | E11: Country | F11: SOVEREIGN | G11: CROP | H11: Drought | I11: 12A | J11: 2025/2026 | K11: 500000 | L11: 7382544 | M11: 23077459 | N11: 0.1475 | O11: 2315000 | Q11: 0.21598272 | R11: 1.6 | S11: =K11/R11 -> 312500 | T11: 375000 | U11: 375000
A12: 12_DR_MR_CROP_SOV_SUD | B12: =UPPER([1]Pools!$B409) -> GHANA SOUTH SHORT-RAINS | C12: WCA | D12: MAURITANIA | E12: Country | F12: SOVEREIGN | G12: CROP | H12: Drought | I12: 12A | J12: 2025/2026 | K12: 1000000 | L12: 8558616 | M12: 24431580 | N12: 0.30699011 | O12: 4872843 | Q12: 0.20521901 | R12: 1.6 | S12: =K12/R12 -> 625000 | T12: 375000 | U12: 375000
A13: 12_DR_NE_CROP_SOV | B13: =UPPER([1]Pools!$B410) -> MALI CROP | C13: WCA | D13: NIGER | E13: Country | F13: SOVEREIGN | G13: CROP | H13: Drought | I13: 12A | J13: 2025/2026 | K13: 330708 | L13: 169310640 | M13: 556423020 | N13: 0.0069395456 | O13: 2686384 | Q13: 0.12310526 | R13: 1.6 | S13: =K13/R13 -> 206692.5 | U13: 65804.5 | V13: 300000
A14: 12_DR_NE_RANGE_SOV | B14: =UPPER([1]Pools!$B411) -> MAURITANIA NORD CROP | C14: WCA | D14: NIGER | E14: Country | F14: SOVEREIGN | G14: CROP | H14: Drought | I14: 12A | J14: 2025/2026 | K14: 400902 | L14: 9223063 | M14: 24037984 | N14: 0.12088637 | O14: 1790922 | Q14: 0.2238523 | R14: 1.6 | S14: =K14/R14 -> 250563.75 | U14: 65804.5 | V14: 300000
A15: 12_DR_SN_CROP_REP_START | B15: =UPPER([1]Pools!$B412) -> MAURITANIA SUD CROP | C15: WCA | D15: SENEGAL | E15: START Network | F15: REPLICA | G15: CROP | H15: Drought | I15: 12A | J15: 2025/2026 | K15: 1050000 | L15: 18097063 | M15: 40566400 | N15: 0.22603715 | O15: 5078905 | Q15: 0.20673748 | R15: 1.6 | S15: =K15/R15 -> 656250 | Y15: 1050000
A16: 12_DR_ML_CROP_REP_UNHCR | B16: =UPPER([1]Pools!$B413) -> NIGER CROP | C16: WCA | D16: MALI | E16: UNHCR | F16: REPLICA | G16: CROP | H16: Drought | I16: 12A | J16: 2025/2026 | K16: 500000 | L16: 31126675 | M16: 61513362 | N16: 0.088703846 | O16: 2695416 | Q16: 0.18550012 | R16: 1.6 | S16: =K16/R16 -> 312500 | U16: 500000
A17: 12_DR_BF_CROP_REP_WFP | B17: =UPPER([1]Pools!$B414) -> NIGER RANGELAND | C17: WCA | D17: BURKINA FASO | E17: WFP | F17: REPLICA | G17: CROP | H17: Drought | I17: 12A | J17: 2025/2026 | K17: 500000 | L17: 45978150 | M17: 104949339 | N17: 0.0508723 | O17: 3000000 | Q17: 0.16666667 | R17: 1.6 | S17: =K17/R17 -> 312500 | U17: 500000
A18: 12_DR_ML_CROP_REP_WFP | B18: =UPPER([1]Pools!$B415) -> REPLICA START SENEGAL CROP | C18: WCA | D18: MALI | E18: WFP | F18: REPLICA | G18: CROP | H18: Drought | I18: 12A | J18: 2025/2026 | K18: 1000000 | L18: 31126675 | M18: 61513361 | N18: 0.1774077 | O18: 5390832 | Q18: 0.18550012 | R18: 1.6 | S18: =K18/R18 -> 625000 | U18: 1000000
A19: 12_DR_MR_RANGE_REP_WFP | B19: =UPPER([1]Pools!$B416) -> REPLICA UNHCR MALI CROP | C19: WCA | D19: MAURITANIA | E19: WFP | F19: REPLICA | G19: RANGELAND | H19: Drought | I19: 12A | J19: 2025/2026 | K19: 500000 | L19: 31893000 | M19: 38422440 | N19: 0.35667071 | O19: 2328860 | Q19: 0.21469732 | R19: 1.6 | S19: =K19/R19 -> 312500 | Z19: 500000
A20: 12_DR_SD_RANGE_REP_WFP | B20: =UPPER([1]Pools!$B417) -> REPLICA WFP BURKINA FASO CROP | C20: WCA | D20: SUDAN | E20: WFP | F20: REPLICA | G20: CROP | H20: Drought | I20: 12A | J20: 2025/2026 | K20: 150000 | L20: 60775827 | M20: 154893331 | N20: 0.0079316383 | O20: 746506 | Q20: 0.20093609 | R20: 1.6 | S20: =K20/R20 -> 93750 | U20: 150000
A21: 12_DR_GM_CROP_REP_WFP | B21: =UPPER([1]Pools!$B418) -> REPLICA WFP MALI CROP | C21: WCA | D21: GAMBIA | E21: WFP | F21: REPLICA | G21: CROP | H21: Drought | I21: 12A | J21: 2025/2026 | K21: 400000 | L21: 1579696 | M21: 17910805 | N21: 0.11825523 | O21: 1931239 | Q21: 0.20712092 | R21: 1.6 | S21: =K21/R21 -> 250000 | Z21: 400000
A22: 12_DR_SN_CROP_SOV | B22: =UPPER([1]Pools!$B419) -> REPLICA WFP MAURITANIA RANGELAND | C22: WCA | D22: SENEGAL | E22: Country | F22: SOVEREIGN | G22: CROP | H22: Drought | I22: 12A | J22: 2025/2026 | K22: 2000000 | L22: 18097063 | M22: 40566400 | N22: 0.43054693 | O22: 9674104 | Q22: 0.20673749 | R22: 1.6 | S22: =K22/R22 -> 1250000 | AC22: 2000000
A23: 12_DR_SM_CROP_SOV_GU | B23: =UPPER([1]Pools!$B420) -> REPLICA WFP SUDAN CROP | C23: ESA | D23: SOMALIA | E23: Country | F23: SOVEREIGN | G23: CROP | H23: Drought | I23: 12A | J23: 2025/2026 | K23: 350000 | L23: 105379358 | M23: 171562206 | N23: 0.025314384 | O23: 1675378 | P23: 0 | Q23: 0.20890808 | R23: 1.6 | S23: =K23/R23 -> 218750 | W23: 350000
A24: 12_DR_SM_RANGE_SOV_GU | B24: =UPPER([1]Pools!$B421) -> REPLICA WFP THE GAMBIA | C24: ESA | D24: SOMALIA | E24: Country | F24: SOVEREIGN | G24: RANGELAND | H24: Drought | I24: 12A | J24: 2025/2026 | K24: 150000 | L24: 246604871 | M24: 405066483 | N24: 0.0026431954 | O24: 418845 | P24: 0 | Q24: 0.35812771 | R24: 1.6 | S24: =K24/R24 -> 93750 | W24: 150000
A25: 12_DR_GM_CROP_SOV | B25: =UPPER([1]Pools!$B422) -> SENEGAL CROP | C25: WCA | D25: GAMBIA | E25: Country | F25: SOVEREIGN | G25: CROP | H25: Drought | I25: 12A | J25: 2025/2026 | K25: 500000 | L25: 1579696 | M25: 17910805 | N25: 0.14781905 | O25: 2414049 | Q25: 0.2071209 | R25: 1.6 | S25: =K25/R25 -> 312500 | AC25: 500000
A26: 12_DR_TG_CROP_SOV_NORD | B26: =UPPER([1]Pools!$B423) -> SOMALIA GU CROP | C26: WCA | D26: TOGO | E26: Country | F26: SOVEREIGN | G26: CROP | H26: Drought | I26: 12A | J26: 2025/2026 | K26: 650000 | L26: 8991702 | M26: 20855081 | N26: 0.265523 | O26: 3150000 | Q26: 0.20634921 | R26: 1.6 | S26: =K26/R26 -> 406250 | T26: 500000
A27: 12_DR_TG_CROP_SOV_SUD | B27: =UPPER([1]Pools!$B424) -> SOMALIA GU RANGELAND | C27: WCA | D27: TOGO | E27: Country | F27: SOVEREIGN | G27: CROP | H27: Drought | I27: 12A | J27: 2025/2026 | K27: 350000 | L27: 10563129 | M27: 18982327 | N27: 0.1452573 | O27: 1222950 | Q27: 0.28619322 | R27: 1.6 | S27: =K27/R27 -> 218750 | V27: 500000
A28: 12_DR_MG_SOV | B28: MADAGASCAR CROP | C28: ESA | D28: MADAGASCAR | E28: Country | F28: SOVEREIGN | G28: CROP | H28: Drought | I28: 12B | J28: 2025/2026 | K28: 500000 | L28: 33676620 | M28: 109592190 | N28: 0.032900234 | O28: 2497640 | Q28: 0.20018898 | R28: 1.6 | S28: =K28/R28 -> 312500 | T28: 250000 | V28: 250000 | W28: 400000
A29: 12_DR_SM_RANGE_SOV_DEYR | B29: SOMALIA DEYR RANGELAND | C29: ESA | D29: SOMALIA | E29: Country | F29: SOVEREIGN | G29: RANGELAND | H29: Drought | I29: 12B | J29: 2025/2026 | K29: 400000 | L29: 118269405 | M29: 412366455 | N29: 0.005217679 | O29: 1534504 | P29: 464257 | Q29: 0.26067055 | R29: 1.6 | S29: =K29/R29 -> 250000 | W29: 1600000
A30: 12_DR_SM_CROP_SOV_DEYR | B30: SOMALIA DEYR CROP | C30: ESA | D30: SOMALIA | E30: Country | F30: SOVEREIGN | G30: CROP | H30: Drought | I30: 12B | J30: 2025/2026 | K30: 1600000 | L30: 118693485 | M30: 187454835 | N30: 0.081427473 | O30: 5599063 | P30: 2974997.1 | Q30: 0.2857621 | R30: 1.6 | S30: =K30/R30 -> 1000000
A31: 12_DR_SM_RANGE_REP_DEYR_START | B31: REPLICA START SOMALIA DEYR RANGELAND | C31: ESA | D31: SOMALIA | E31: START Network | F31: REPLICA | G31: RANGELAND | H31: Drought | I31: 12B | J31: 2025/2026 | K31: 150000 | L31: 148720815 | M31: 412366455 | N31: 0.0024229947 | O31: 638812 | P31: 141808.98 | Q31: 0.23481087 | R31: 1.6 | S31: =K31/R31 -> 93750 | Y31: 150000
A32: 12_DR_SM_CROP_REP_DEYR_START | B32: REPLICA START SOMALIA DEYR CROP | C32: ESA | D32: SOMALIA | E32: START Network | F32: REPLICA | G32: CROP | H32: Drought | I32: 12B | J32: 2025/2026 | K32: 600000 | L32: 134303508 | M32: 187454835 | N32: 0.049623145 | O32: 2637536 | P32: 1038390.2 | Q32: 0.22748505 | R32: 1.6 | S32: =K32/R32 -> 375000 | Y32: 600000
A33: 12_DR_SM_CROP_REP_DEYR_WFP | B33: REPLICA WFP SOMALIA DEYR CROP | C33: ESA | D33: SOMALIA | E33: WFP | F33: REPLICA | G33: CROP | H33: Drought | I33: 12B | J33: 2025/2026 | K33: 500000 | L33: 134303508 | M33: 187454835 | N33: 0.041352627 | O33: 2197947 | P33: 865325.31 | Q33: 0.22748501 | R33: 1.6 | S33: =K33/R33 -> 312500 | Z33: 500000
A34: 12_TC_KM_SOV | B34: COMOROS TROPICAL CYCLONE | C34: ESA | D34: COMOROS | E34: Country | F34: SOVEREIGN | G34: TROPICAL CYCLONE | H34: Tropical Cyclone | I34: 12B | J34: 2025/2026 | K34: 500000 | L34: 15024468 | M34: 22870964 | N34: 0.69999997 | O34: 5492547 | Q34: =K34/O34 -> 0.091032448 | R34: 1.65 | S34: =K34/R34 -> 303030.3 | W34: 500000
A35: 12_FL_MG_SOV | C35: ESA | D35: MADAGASCAR | E35: Country | F35: SOVEREIGN | G35: FLOOD | H35: Flood | I35: 12B | J35: 2025/2026 | K35: 1000000 | L35: 70768195 | M35: 123012850 | N35: =O35/(M35-L35) -> 0.14546943 | O35: 7600000 | P35: 0 | Q35: =K35/O35 -> 0.13157895 | R35: 1.65 | S35: =K35/R35 -> 606060.61
A36: 12_TC_MG_SOV | B36: MADAGASCAR | C36: ESA | D36: MADAGASCAR | E36: Country | F36: SOVEREIGN | G36: TROPICAL CYCLONE | H36: Tropical Cyclone | I36: 12B | J36: 2025/2026 | K36: 1800000 | L36: 189499656 | M36: 3549195735 | N36: 0.0026788137 | O36: 9000000 | P36: 5641984.2 | Q36: 0.2 | R36: 1.65 | S36: =K36/R36 -> 1090909.1 | W36: 1800000
A37: 12_TC_MG_REP_START | B37: REPLICA START MADAGASCAR | C37: ESA | D37: MADAGASCAR | E37: START Network | F37: REPLICA | G37: TROPICAL CYCLONE | H37: Tropical Cyclone | I37: 12B | J37: 2025/2026 | K37: 500000 | L37: 189499656 | M37: 2647864330 | N37: 0.0014237107 | O37: 3500000 | P37: 2998548.6 | Q37: 0.14285714 | R37: 1.65 | S37: 303030.3 | Y37: 500000
A38: 12_TC_MG_REP_WFP | B38: REPLICA WFP MADAGASCAR | C38: ESA | D38: MADAGASCAR | E38: WFP | F38: REPLICA | G38: TROPICAL CYCLONE | H38: Tropical Cyclone | I38: 12B | J38: 2025/2026 | K38: 250000 | L38: 282296200 | M38: 6308379185 | N38: 0.00041486319 | O38: 2500000 | P38: 796768.47 | Q38: 0.1 | R38: 1.65 | S38: 151515.15 | Z38: 250000
A39: 12_TC_MZ_REP_WFP | B39: REPLICA WFP MOZAMBIQUE | C39: ESA | D39: MOZAMBIQUE | E39: WFP | F39: REPLICA | G39: TROPICAL CYCLONE | H39: Tropical Cyclone | I39: 12B | J39: 2025/2026 | K39: 376000 | L39: 274280408 | M39: 554906120 | N39: 0.01052524 | O39: 2953653 | Q39: 0.12729999 | R39: 1.65 | S39: 227878.79 | Z39: 376000
A40: 12_DR_MZ_Z1_REP_WFP | B40: REPLICA WFP MOZAMBIQUE | C40: ESA | D40: MOZAMBIQUE | E40: WFP | F40: REPLICA | G40: CROP | H40: Drought | I40: 12B | J40: 2025/2026 | K40: 250000 | L40: 15202530 | M40: 20026304 | N40: 0.21139133 | O40: 1019704 | Q40: 0.24516919 | R40: 1.6 | S40: 156250 | Z40: 250000
...

Sheet Sheet1
A1: Pool | B1: Total Premium | C1: KFW Financed Premium | D1: %
A2: 12B | B2: =SUMIFS('SOV&REPLICA'!$K$2:$K$291,'SOV&REPLICA'!$I$2:$I$291,Sheet1!A2) -> 20476000 | C2: =SUMIFS('SOV&REPLICA'!$U$2:$U$291,'SOV&REPLICA'!$I$2:$I$291,Sheet1!A2) -> 0 | D2: =C2/B2 -> 0
A3: 11B | B3: =SUMIFS('SOV&REPLICA'!$K$2:$K$291,'SOV&REPLICA'!$I$2:$I$291,Sheet1!A3) -> 24086638 | C3: =SUMIFS('SOV&REPLICA'!$U$2:$U$291,'SOV&REPLICA'!$I$2:$I$291,Sheet1!A3) -> 3907800 | D3: =C3/B3 -> 0.16223933
A4: 10B | B4: =SUMIFS('SOV&REPLICA'!$K$2:$K$291,'SOV&REPLICA'!$I$2:$I$291,Sheet1!A4) -> 22361889 | C4: =SUMIFS('SOV&REPLICA'!$U$2:$U$291,'SOV&REPLICA'!$I$2:$I$291,Sheet1!A4) -> 5750000 | D4: =C4/B4 -> 0.25713391
A5: 9 | B5: =SUMIFS('SOV&REPLICA'!$K$2:$K$291,'SOV&REPLICA'!$I$2:$I$291,Sheet1!A5) -> 22143132 | C5: =SUMIFS('SOV&REPLICA'!$U$2:$U$291,'SOV&REPLICA'!$I$2:$I$291,Sheet1!A5) -> 1342818 | D5: =C5/B5 -> 0.060642641
A6: 8 | B6: =SUMIFS('SOV&REPLICA'!$K$2:$K$291,'SOV&REPLICA'!$I$2:$I$291,Sheet1!A6) -> 30359688 | C6: =SUMIFS('SOV&REPLICA'!$U$2:$U$291,'SOV&REPLICA'!$I$2:$I$291,Sheet1!A6) -> 10405221 | D6: =C6/B6 -> 0.34273149
A7: 7 | B7: =SUMIFS('SOV&REPLICA'!$K$2:$K$291,'SOV&REPLICA'!$I$2:$I$291,Sheet1!A7) -> 20728697 | C7: =SUMIFS('SOV&REPLICA'!$U$2:$U$291,'SOV&REPLICA'!$I$2:$I$291,Sheet1!A7) -> 12598952 | D7: =C7/B7 -> 0.60780241
A8: 6 | B8: =SUMIFS('SOV&REPLICA'!$K$2:$K$291,'SOV&REPLICA'!$I$2:$I$291,Sheet1!A8) -> 16049587 | C8: =SUMIFS('SOV&REPLICA'!$U$2:$U$291,'SOV&REPLICA'!$I$2:$I$291,Sheet1!A8) -> 7233637 | D8: =C8/B8 -> 0.45070549
A9: 5 | B9: =SUMIFS('SOV&REPLICA'!$K$2:$K$291,'SOV&REPLICA'!$I$2:$I$291,Sheet1!A9) -> 4814683 | C9: =SUMIFS('SOV&REPLICA'!$U$2:$U$291,'SOV&REPLICA'!$I$2:$I$291,Sheet1!A9) -> 0 | D9: =C9/B9 -> 0
A10: 4 | B10: =SUMIFS('SOV&REPLICA'!$K$2:$K$291,'SOV&REPLICA'!$I$2:$I$291,Sheet1!A10) -> 8740902 | C10: =SUMIFS('SOV&REPLICA'!$U$2:$U$291,'SOV&REPLICA'!$I$2:$I$291,Sheet1!A10) -> 0 | D10: =C10/B10 -> 0
A11: 3 | B11: =SUMIFS('SOV&REPLICA'!$K$2:$K$291,'SOV&REPLICA'!$I$2:$I$291,Sheet1!A11) -> 11310491 | C11: =SUMIFS('SOV&REPLICA'!$U$2:$U$291,'SOV&REPLICA'!$I$2:$I$291,Sheet1!A11) -> 0 | D11: =C11/B11 -> 0
A12: 2 | B12: =SUMIFS('SOV&REPLICA'!$K$2:$K$291,'SOV&REPLICA'!$I$2:$I$291,Sheet1!A12) -> 24792269 | C12: =SUMIFS('SOV&REPLICA'!$U$2:$U$291,'SOV&REPLICA'!$I$2:$I$291,Sheet1!A12) -> 0 | D12: =C12/B12 -> 0
A13: 1 | B13: =SUMIFS('SOV&REPLICA'!$K$2:$K$291,'SOV&REPLICA'!$I$2:$I$291,Sheet1!A13) -> 17000000 | C13: =SUMIFS('SOV&REPLICA'!$U$2:$U$291,'SOV&REPLICA'!$I$2:$I$291,Sheet1!A13) -> 0 | D13: =C13/B13 -> 0

Sheet IIS
A1: Programme Name | B1: Start Date | C1: End date | D1: Pool | E1: Country | F1: Insurance Company | G1: Other Key Partners | H1: Reinsurance type | I1: Original Currency | J1: Exchange rate to USD | K1: ARC Gross Premium ($) | L1: ARC Net Premium | M1: Facultative Reinsurance Premium | N1: ARC Commission | O1: Other provider fees | P1: Total SI ($) | Q1: ARC SI ($) | R1: Total Payout ($) | S1: ARC's payout ($) | T1: Recovery from Fac ($) | U1: Comments
A2: L'Oreal | B2: 45078 | C2: 45199 | D2: 10 | E2: Burkina Faso | F2: Axa | G2: Axa1 | H2: Treaty | I2: XOF | J2: 597.69291 | K2: 15105 | L2: 15105 | M2: 0 | N2: 0 | O2: 0 | P2: 150793.16 | Q2: 150793.16 | R2: 5562 | S2: 5562 | T2: 0 | U2: Payout finalised
A3: WFP Rice_Cote D’ivoire | B3: 45108 | C3: 45291 | D3: 10 | E3: Cote D’ivoire | F3: Consortium | G3: Axa | H3: Treaty | I3: XOF | J3: 611.03 | K3: 13353.289 | L3: 13353.289 | M3: 0 | N3: 0 | O3: 0 | P3: 160883 | Q3: 160883 | R3: 6198.3169 | S3: 6198.3169 | T3: 0 | U3: Payout finalised
A4: Malawi Social Protection | B4: 45231 | C4: 45412 | D4: 10 | E4: Malawi | F4: ARC Ltd | G4: Descartes | H4: Treaty | I4: USD | J4: 1 | K4: 5127443.3 | L4: 1664609.8 | M4: 3457266.5 | O4: 5567 | P4: 9128383 | Q4: 2966724.5 | R4: 6610660 | S4: 2148464.5 | T4: 4462195.5 | U4: Payout finalised
A5: DRIVE_Somalia | B5: 45200 | C5: 45565 | D5: 10 | E5: Somalia | F5: Zep-Re | G5: ACRE Africa | H5: Treaty | I5: USD | J5: 1 | K5: 229889.56 | L5: 229889.56 | M5: 0 | N5: 0 | O5: 0 | P5: 1159876.1 | Q5: 1159876.1 | R5: 0 | U5: Payout finalised
A6: DRIVE_Ethiopia (Somali Region) | B6: 45200 | C6: 45565 | D6: 10 | E6: Ethiopia | F6: Zep-Re | G6: ACRE Africa | H6: Treaty | I6: USD | J6: 1 | K6: 28437.081 | L6: 28437.081 | M6: 0 | N6: 0 | O6: 0 | P6: 133558.68 | Q6: 133558.68 | R6: 1889.5711 | S6: 1889.5711 | U6: Payout finalised
A7: DRIVE_Ethiopia (excl Somali Region) | B7: 45200 | C7: 45565 | D7: 10 | E7: Ethiopia | F7: Zep-Re | G7: ACRE Africa | H7: Treaty | I7: USD | J7: 1 | K7: 46738.694 | L7: 46738.694 | M7: 0 | N7: 0 | O7: 0 | P7: 221537.37 | Q7: 221537.37 | U7: Payout finalised
A8: DRIVE_Kenya | B8: 45200 | C8: 45565 | D8: 10 | E8: Kenya | F8: Zep-Re | G8: ACRE Africa | H8: Treaty | I8: USD | J8: 1 | K8: 70323.012 | L8: 70323.012 | M8: 0 | N8: 0 | O8: 0 | P8: 317988.95 | Q8: 317988.95 | U8: Payout finalised
A9: DRIVE_Somalia_MAM24 | B9: 45383 | C9: 45746 | D9: 10 | E9: Somalia | F9: Zep-Re | G9: ACRE Africa | H9: Treaty | I9: USD | J9: 1 | K9: 3528.8667 | L9: 3528.8667 | M9: 0 | N9: 0 | O9: 0 | P9: 17831.67 | Q9: 17831.67 | U9: Payout finalised
A10: DRIVE_Ethiopia (Somali Region)_MAM24 | B10: 45352 | C10: 45716 | D10: 10 | E10: Ethiopia | F10: Zep-Re | G10: ACRE Africa | H10: Treaty | I10: USD | J10: 1 | K10: 68742.122 | L10: 68742.122 | M10: 0 | N10: 0 | O10: 0 | P10: 308126.12 | Q10: 308126.12 | R10: 15287 | S10: 15287 | U10: Payout finalised
A11: DRIVE_Ethiopia (excl Somali Region)_MAM24 | B11: 45352 | C11: 45716 | D11: 10 | E11: Ethiopia | F11: Zep-Re | G11: ACRE Africa | H11: Treaty | I11: USD | J11: 1 | K11: 85499.825 | L11: 85499.825 | M11: 0 | N11: 0 | O11: 0 | P11: 426602.15 | Q11: 426602.15 | U11: Payout finalised
A12: DRIVE_Kenya_MAM24 | B12: 45352 | C12: 45716 | D12: 10 | E12: Kenya | F12: Zep-Re | G12: ACRE Africa | H12: Treaty | I12: USD | J12: 1 | K12: 60582.624 | L12: 60582.624 | M12: 0 | N12: 0 | O12: 0 | P12: 278247.9 | Q12: 278247.9 | R12: 381 | S12: 381 | U12: Payout finalised
A13: OAF_Kenya | B13: 45323 | C13: 45657 | D13: 10 | E13: Kenya | F13: Mayfair Insurance | G13: Risk Shield | H13: Treaty | I13: USD | J13: 1 | K13: 27793.66 | L13: 27793.66 | M13: 0 | N13: 0 | O13: 0 | P13: 1400000 | Q13: 1400000 | R13: 46308.389 | S13: 46308.389 | T13: 0 | U13: Payout finalised
A14: Republic of Djibouti _Excess rainfall | B14: 45306 | C14: 45671 | D14: 10 | E14: Djibouti | F14: ARC Ltd | G14: Descartes | H14: Treaty | I14: USD | J14: 1 | K14: 250000 | L14: 9391.13 | M14: 240608.87 | N14: 0 | O14: 3108.87 | P14: 1487636 | Q14: 74381.798 | U14: Payout finalised
A15: Republic of Djibouti _Drought | B15: 45352 | C15: 45716 | D15: 10 | E15: Djibouti | F15: ARC Ltd | G15: Descartes | H15: Treaty | I15: USD | J15: 1 | K15: 150000 | L15: 4391.13 | M15: 145608.87 | N15: 0 | O15: 3108.87 | P15: 768315 | Q15: 38415.75 | U15: Waiting for final report
A16: WFP R4Madagascar (Rainy) | B16: 45247 | C16: 45412 | D16: 10 | E16: Madagascar | F16: Assurances Reasssurances Omnibranches (ARO) | G16: Pula | H16: ARC Ltd | I16: MGA | J16: 4574.51 | K16: 69532.992 | L16: 16703.137 | M16: 15867.98 | N16: 835.15685 | O16: 36126.717 | P16: 431420.48 | Q16: 215710.24 | R16: 35167.052 | S16: 17583.526 | T16: 17583.526 | U16: Payout finalised
A17: WFP R4Madagascar (Dry) | B17: 45383 | C17: 45626 | D17: 10 | E17: Madagascar | F17: Assurances Reasssurances Omnibranches (ARO) | G17: Pula | H17: ARC Ltd | I17: MGA | J17: 4574.51 | K17: 68693.024 | L17: 21511.528 | M17: 20435.951 | N17: 1075.5764 | O17: 25669.969 | P17: 431420.48 | Q17: 215710.24 | R17: 10104.657 | S17: 5052.3284 | T17: 5052.3284 | U17: Payout finalised
A18: L'Oreal | B18: 45444 | C18: 45565 | D18: 11 | E18: Burkina Faso | F18: Axa | G18: Axa | H18: Treaty | I18: XOF | J18: 597.69291 | K18: 7646.84 | L18: 7646.84 | M18: 0 | N18: 0 | O18: 0 | P18: 75396.578 | Q18: 75396.578 | R18: 0 | S18: 0 | T18: 0 | U18: Payout finalised
A19: WFP Rice_Cote D’ivoire | B19: 45474 | C19: 45657 | D19: 11 | E19: Cote D’ivoire | F19: Consortium | G19: Axa | H19: Treaty | I19: XOF | J19: 611.03 | K19: 61499.433 | L19: 61499.433 | M19: 0 | N19: 0 | O19: 0 | P19: 869566 | Q19: 869566 | R19: 89428.973 | S19: 89428.973 | T19: 0 | U19: Payout finalised/ outstanding payout
A20: BOAD_Excess Precipitation | B20: 45505 | C20: 45747 | D20: 11 | E20: West Africa | F20: ARC Ltd | G20: Munich Re | H20: ARC Ltd | I20: Euro | J20: 0.9 | K20: 2083333.3 | L20: 0 | M20: 1796875 | N20: 234375 | O20: 52083.333 | P20: 26393941 | Q20: 0 | R20: 6858948.2 | S20: 0 | T20: 6858948.2 | U20: IN Risk
A21: BOAD_Infectious_Disease | B21: 45505 | C21: 45747 | D21: 11 | E21: West Africa | F21: ARC Ltd | G21: Munich Re | H21: ARC Ltd | I21: Euro | J21: 0.9 | K21: 583333.33 | L21: 0 | M21: 517708.33 | N21: 65625 | P21: 13919727 | Q21: 0 | U21: IN Risk
A22: BOAD_Drought | B22: 45505 | C22: 45747 | D22: 11 | E22: West Africa | F22: ARC Ltd | G22: Munich Re | H22: ARC Ltd | I22: Euro | J22: 0.9 | K22: 1500000 | L22: 75000 | M22: 1256250 | N22: 168750 | P22: 21525348 | Q22: 1076267.4 | R22: 0 | S22: 0 | T22: 0 | U22: Payout finalised
A23: WFP Gambia | B23: 45464 | C23: 45596 | D23: 11 | E23: Gambia | F23: ARC Ltd | G23: CNAAS and Continental Re | H23: Fac Oblig | I23: USD | J23: 1 | K23: 93281 | L23: 27657.5 | M23: 26274.625 | N23: 3882.875 | O23: 35466 | P23: 523221.59 | Q23: 261610.8 | R23: 0 | S23: 0 | T23: 0 | U23: Payout finalised
A24: DRIVE_Somalia | B24: 45566 | C24: 45930 | D24: 11 | E24: Somalia | F24: Zep-Re | G24: ACRE Africa | H24: Treaty | I24: USD | J24: 1 | K24: 40469.49 | L24: 40469.49 | P24: 189997.65 | Q24: 189997.65 | R24: 12396.328 | S24: 12396.328 | U24: IN Risk
A25: DRIVE_Ethiopia (Somali Region) | B25: 45566 | C25: 45930 | D25: 11 | E25: Ethiopia | F25: Zep-Re | G25: ACRE Africa | H25: Treaty | I25: USD | J25: 1 | K25: 23044.028 | L25: 23044.028 | P25: 110788.61 | Q25: 110788.61 | R25: 2593.5414 | S25: 2593.5414 | U25: IN Risk
A26: DRIVE_Ethiopia (excl Somali Region) | B26: 45566 | C26: 45930 | D26: 11 | E26: Ethiopia | F26: Zep-Re | G26: ACRE Africa | H26: Treaty | I26: USD | J26: 1 | K26: 46573.35 | L26: 46573.35 | P26: 223910.4 | Q26: 223910.4 | U26: IN Risk
A27: DRIVE_Kenya | B27: 45566 | C27: 45930 | D27: 11 | E27: Kenya | F27: Zep-Re | G27: ACRE Africa | H27: Treaty | I27: USD | J27: 1 | K27: 138437.64 | L27: 138437.64 | P27: 667010.4 | Q27: 667010.4 | R27: 863.62693 | S27: 863.62693 | U27: IN Risk
A28: Malawi Social Protection | B28: 45597 | C28: 45777 | D28: 11 | E28: Malawi | F28: ARC Ltd | G28: Descartes | H28: Treaty | I28: USD | J28: 1 | K28: 5127443.3 | L28: 1664609.8 | M28: 3457266.5 | O28: 5567 | P28: 9740073 | Q28: 3165523.7 | R28: 356063 | S28: 115720.48 | T28: 240342.52 | U28: IN Risk
A29: One Acre Fund Malawi | B29: 45611 | C29: 45884 | D29: 11 | E29: Malawi | F29: BRITAM INS RETENTION | G29: Risk Shield | H29: Fac Oblig | I29: USD | J29: 1 | K29: 11807.145 | L29: 7797.4509 | M29: 4009.6937 | P29: 558326.05 | Q29: 368719.12 | U29: IN Risk
A30: WFP Malawi | B30: 45611 | C30: 45884 | D30: 11 | E30: Malawi | F30: BRITAM INS RETENTION | G30: Risk Shield | H30: Fac Oblig | I30: USD | J30: 1 | K30: 1557.2615 | L30: 1557.2615 | P30: 50592 | Q30: 50592 | U30: IN Risk
A31: OAF_Kenya | B31: 45689 | C31: 46022 | D31: 11 | E31: Kenya | F31: Mayfair Insurance | G31: Risk Shield | H31: Fac Oblig | I31: USD | J31: 1 | K31: 23475.898 | L31: 15503.508 | M31: 7972.39 | P31: 1208464.2 | Q31: 798071.08 | U31: IN Risk
A32: WFP R4Madagascar | B32: 45627 | C32: 45808 | D32: 11 | E32: Madagascar | F32: Assurances Reasssurances Omnibranches (ARO) | G32: ARC Ltd | H32: Fac Oblig | I32: MGA | J32: 4683.97 | K32: 144483.4 | L32: 109774.4 | N32: 34709 | P32: 1002374.8 | Q32: 1002374.8 | U32: IN Risk
A33: Flood Togo | B33: 45658 | C33: 46022 | D33: 11 | E33: Togo | F33: SUNU | G33: ARC Ltd | H33: Fac Oblig | I33: Euro | J33: 0.9 | K33: 153309.41 | L33: 100323.93 | M33: 40129.573 | N33: 12855.906 | P33: 445884.15 | Q33: 312118.9 | U33: Under review
A34: Republic of Djibouti _Excess rainfall | B34: 45672 | C34: 46036 | D34: 11 | E34: Djibouti | F34: ARC Ltd | G34: Descartes | H34: Treaty | I34: USD | J34: 1 | K34: 250000 | L34: 21891.13 | M34: 225000 | N34: 0 | O34: 3108.87 | P34: 1487636 | Q34: 148763.6 | U34: IN Risk
A35: Republic of Djibouti _Drought | B35: 45717 | C35: 46081 | D35: 11 | E35: Djibouti | F35: ARC Ltd | G35: Descartes | H35: Treaty | I35: USD | J35: 1 | K35: 150000 | L35: 11891.13 | M35: 135000 | N35: 0 | O35: 3108.87 | P35: 768315 | Q35: 76831.5 | U35: IN Risk
A36: CREST (potential) | B36: 45717 | C36: 46184 | D36: 11 | E36: Kenya | F36: ARC Ltd | G36: ARC Ltd | H36: Fac Oblig | I36: USD | J36: 1 | K36: 392852.69 | L36: 392852.69 | M36: 0 | P36: 2006960 | Q36: 2006960 | U36: Under review
